<?xml version="1.0"?>
<robot xmlns:xacro="http://www.ros.org/wiki/xacro" name="basic_robot">

  <!-- Parameters -->
  <xacro:property name="wheel_radius" value="0.1"/>
  <xacro:property name="wheel_width" value="0.05"/>
  <xacro:property name="wheel_offset" value="0.25"/>

  <!-- Base Link -->
  <link name="base_link">
    <visual>
      <geometry>
        <box size="0.5 0.3 0.1"/>
      </geometry>
      <material name="blue">
        <color rgba="0.0 0.0 1.0 1.0"/>
      </material>
    </visual>
  </link>

  <!-- Macro for Wheels -->
  <xacro:macro name="wheel" params="wheel_name x y z">
    <link name="${wheel_name}">
      <visual>
        <geometry>
          <cylinder radius="${wheel_radius}" length="${wheel_width}"/>
        </geometry>
        <material name="black">
          <color rgba="0.0 0.0 0.0 1.0"/>
        </material>
      </visual>
    </link>
    <joint name="${wheel_name}_joint" type="continuous">
      <parent link="base_link"/>
      <child link="${wheel_name}"/>
      <origin xyz="${x} ${y} ${z}" rpy="0 0 0"/>
      <axis xyz="0 1 0"/>
    </joint>
  </xacro:macro>

  <!-- Add Wheels -->
  <xacro:wheel wheel_name="left_wheel" x="0.3" y="${wheel_offset}" z="0"/>
  <xacro:wheel wheel_name="right_wheel" x="0.3" y="-${wheel_offset}" z="0"/>

</robot>
